<mujoco model="teaching_humanoid">
  <compiler angle="radian" inertiafromgeom="true" autolimits="true"/>
  <option timestep="0.002" gravity="0 0 -9.81" integrator="implicitfast">
    <flag contact="enable"/>
  </option>

  <visual>
    <headlight ambient="0.4 0.4 0.4" diffuse="0.8 0.8 0.8" specular="0.1 0.1 0.1"/>
    <rgba contactpoint="1 0 0 1" contactforce="1 0.3 0.1 1"/>
    <global azimuth="135" elevation="-18"/>
  </visual>

  <default>
    <joint damping="3" armature="0.02" limited="true"/>
    <geom friction="0.9 0.005 0.0001" condim="3" solref="0.01 1" solimp="0.9 0.95 0.001"/>
    <position kp="140" ctrllimited="true"/>
  </default>

  <asset>
    <texture name="grid" type="2d" builtin="checker" rgb1="0.25 0.25 0.25" rgb2="0.35 0.35 0.35" width="512" height="512"/>
    <material name="floor_mat" texture="grid" texrepeat="8 8" reflectance="0.05"/>
    <material name="pelvis_mat" rgba="0.18 0.35 0.65 1"/>
    <material name="torso_mat" rgba="0.22 0.45 0.78 1"/>
    <material name="left_mat" rgba="0.25 0.65 0.35 1"/>
    <material name="right_mat" rgba="0.85 0.35 0.25 1"/>
    <material name="dark_mat" rgba="0.15 0.15 0.18 1"/>
  </asset>

  <worldbody>
    <light pos="0 0 3" dir="0 0 -1" directional="true"/>
    <geom name="floor" type="plane" size="5 5 0.1" material="floor_mat" friction="0.9 0.005 0.0001"/>

    <body name="pelvis" pos="0 0 0.87">
      <freejoint name="root"/>
      <geom name="pelvis_geom" type="box" size="0.12 0.09 0.08" mass="6.0" material="pelvis_mat"/>
      <site name="pelvis_imu" pos="0 0 0" size="0.015" rgba="1 1 0 1"/>

      <body name="torso" pos="0 0 0.08">
        <geom name="torso_geom" type="capsule" fromto="0 0 0 0 0 0.38" size="0.09" mass="9.0" material="torso_mat"/>
        <body name="head" pos="0 0 0.47">
          <geom name="head_geom" type="sphere" size="0.095" mass="2.5" material="dark_mat"/>
        </body>
        <body name="left_arm" pos="0 0.12 0.32">
          <geom name="left_arm_geom" type="capsule" fromto="0 0 0 0 0 -0.42" size="0.035" mass="1.8" material="left_mat" contype="0" conaffinity="0"/>
        </body>
        <body name="right_arm" pos="0 -0.12 0.32">
          <geom name="right_arm_geom" type="capsule" fromto="0 0 0 0 0 -0.42" size="0.035" mass="1.8" material="right_mat" contype="0" conaffinity="0"/>
        </body>
      </body>

      <body name="left_thigh" pos="0 0.10 -0.08">
        <joint name="left_hip_yaw" type="hinge" axis="0 0 1" range="-0.6 0.6"/>
        <joint name="left_hip_roll" type="hinge" axis="1 0 0" range="-0.5 0.5"/>
        <joint name="left_hip_pitch" type="hinge" axis="0 1 0" range="-1.2 1.0"/>
        <geom name="left_thigh_geom" type="capsule" fromto="0 0 0 0 0 -0.36" size="0.055" mass="4.0" material="left_mat"/>
        <body name="left_shin" pos="0 0 -0.36">
          <joint name="left_knee" type="hinge" axis="0 1 0" range="0 2.1"/>
          <geom name="left_shin_geom" type="capsule" fromto="0 0 0 0 0 -0.36" size="0.047" mass="3.0" material="left_mat"/>
          <body name="left_foot" pos="0 0 -0.36">
            <joint name="left_ankle_pitch" type="hinge" axis="0 1 0" range="-0.8 0.8"/>
            <joint name="left_ankle_roll" type="hinge" axis="1 0 0" range="-0.5 0.5"/>
            <geom name="left_foot_geom" type="box" pos="0.07 0 -0.035" size="0.13 0.06 0.035" mass="1.2" material="left_mat"/>
            <site name="left_foot_touch_site" type="box" pos="0.07 0 -0.067" size="0.13 0.06 0.012" rgba="0 1 0 0.25"/>
          </body>
        </body>
      </body>

      <body name="right_thigh" pos="0 -0.10 -0.08">
        <joint name="right_hip_yaw" type="hinge" axis="0 0 1" range="-0.6 0.6"/>
        <joint name="right_hip_roll" type="hinge" axis="1 0 0" range="-0.5 0.5"/>
        <joint name="right_hip_pitch" type="hinge" axis="0 1 0" range="-1.2 1.0"/>
        <geom name="right_thigh_geom" type="capsule" fromto="0 0 0 0 0 -0.36" size="0.055" mass="4.0" material="right_mat"/>
        <body name="right_shin" pos="0 0 -0.36">
          <joint name="right_knee" type="hinge" axis="0 1 0" range="0 2.1"/>
          <geom name="right_shin_geom" type="capsule" fromto="0 0 0 0 0 -0.36" size="0.047" mass="3.0" material="right_mat"/>
          <body name="right_foot" pos="0 0 -0.36">
            <joint name="right_ankle_pitch" type="hinge" axis="0 1 0" range="-0.8 0.8"/>
            <joint name="right_ankle_roll" type="hinge" axis="1 0 0" range="-0.5 0.5"/>
            <geom name="right_foot_geom" type="box" pos="0.07 0 -0.035" size="0.13 0.06 0.035" mass="1.2" material="right_mat"/>
            <site name="right_foot_touch_site" type="box" pos="0.07 0 -0.067" size="0.13 0.06 0.012" rgba="0 1 0 0.25"/>
          </body>
        </body>
      </body>
    </body>
  </worldbody>

  <equality>
    <weld name="pelvis_weld" body1="pelvis"/>
  </equality>

  <actuator>
    <position name="left_hip_yaw_act" joint="left_hip_yaw" ctrlrange="-0.6 0.6"/>
    <position name="left_hip_roll_act" joint="left_hip_roll" ctrlrange="-0.5 0.5"/>
    <position name="left_hip_pitch_act" joint="left_hip_pitch" ctrlrange="-1.2 1.0"/>
    <position name="left_knee_act" joint="left_knee" ctrlrange="0 2.1"/>
    <position name="left_ankle_pitch_act" joint="left_ankle_pitch" ctrlrange="-0.8 0.8"/>
    <position name="left_ankle_roll_act" joint="left_ankle_roll" ctrlrange="-0.5 0.5"/>
    <position name="right_hip_yaw_act" joint="right_hip_yaw" ctrlrange="-0.6 0.6"/>
    <position name="right_hip_roll_act" joint="right_hip_roll" ctrlrange="-0.5 0.5"/>
    <position name="right_hip_pitch_act" joint="right_hip_pitch" ctrlrange="-1.2 1.0"/>
    <position name="right_knee_act" joint="right_knee" ctrlrange="0 2.1"/>
    <position name="right_ankle_pitch_act" joint="right_ankle_pitch" ctrlrange="-0.8 0.8"/>
    <position name="right_ankle_roll_act" joint="right_ankle_roll" ctrlrange="-0.5 0.5"/>
  </actuator>

  <sensor>
    <accelerometer name="pelvis_accelerometer" site="pelvis_imu"/>
    <gyro name="pelvis_gyro" site="pelvis_imu"/>
    <framequat name="pelvis_orientation" objtype="body" objname="pelvis"/>
    <subtreecom name="humanoid_com" body="pelvis"/>
    <touch name="left_foot_force" site="left_foot_touch_site"/>
    <touch name="right_foot_force" site="right_foot_touch_site"/>
  </sensor>

  <keyframe>
    <key name="stand"
         qpos="0 0 0.87 1 0 0 0  0 0 0 0 0 0  0 0 0 0 0 0"
         ctrl="0 0 0 0 0 0  0 0 0 0 0 0"/>
    <key name="crouch"
         qpos="0 0 0.81 1 0 0 0  0 0 -0.45 0.90 -0.45 0  0 0 -0.45 0.90 -0.45 0"
         ctrl="0 0 -0.45 0.90 -0.45 0  0 0 -0.45 0.90 -0.45 0"/>
  </keyframe>
</mujoco>
